<?xml version="1.0" ?>
<sdf version="1.5">
  <model name="Open_UMA_Extended">  
  <static>false</static>

  <!-- ****************** ROBOT BASE FOOTPRINT ***************************  -->
  <pose>0.0 0.0 0.0 0.0 0.0 0.0</pose>
  <link name="base_footprint"/>

  <!-- ********************** ROBOT BASE *********************************  -->
  <link name="base_link">
    
    <inertial>
      <mass>2</mass>
      <inertia>
        <ixx>0.00545</ixx>
        <ixy>0</ixy>
        <ixz>0</ixz>
        <iyy>0.00841</iyy>
        <iyz>0</iyz>
        <izz>0.0131</izz>
      </inertia>
    </inertial>

    <collision name="base_collision">
      <pose>0 0 0.053 0 0 0</pose>
      <geometry>
        <box>
          <!--    X(largo)    Y(ancho)    Z(alto)     -->
          <size>0.220 0.175 0.046</size>
        </box>
      </geometry>
    </collision>

    <visual name="base_visual">
      <!-- Z= 0.058-0.005 ROLL PITCH YAW-->
      <pose>0 0 0.053 0 0 0</pose>
      <geometry>
        <box>
          <!--    X    Y    Z     -->
          <size>0.220 0.175 0.046</size>
        </box>
      </geometry>
      <material>
        <script>
          <uri>/usr/share/gazebo-11/media/materials/scripts/gazebo.material</uri>
          <name>Gazebo/Orange</name>
        </script>
      </material>
    </visual>
  </link>

  <!-- *********************** IMU SENSOR SETUP **************************  -->
  <link name="imu_link">
    <gravity>true</gravity>
    <sensor name="bmb_imu" type="imu">
      <always_on>true</always_on>
      <update_rate>100</update_rate>
      <visualize>true</visualize>
      <imu>
        <orientation>
          <x>
            <noise type="gaussian">
              <mean>0.0</mean>
              <stddev>2e-3</stddev>
            </noise>
          </x>
          <y>
            <noise type="gaussian">
              <mean>0.0</mean>
              <stddev>2e-3</stddev>
            </noise>
          </y>
          <z>
            <noise type="gaussian">
              <mean>0.0</mean>
              <stddev>2e-3</stddev>
            </noise>
          </z>
        </orientation>
        <angular_velocity>
          <x>
            <noise type="gaussian">
              <mean>0.0</mean>
              <stddev>2e-4</stddev>
            </noise>
          </x>
          <y>
            <noise type="gaussian">
              <mean>0.0</mean>
              <stddev>2e-4</stddev>
            </noise>
          </y>
          <z>
            <noise type="gaussian">
              <mean>0.0</mean>
              <stddev>2e-4</stddev>
            </noise>
          </z>
        </angular_velocity>
        <linear_acceleration>
          <x>
            <noise type="gaussian">
              <mean>0.0</mean>
              <stddev>1.7e-2</stddev>
            </noise>
          </x>
          <y>
            <noise type="gaussian">
              <mean>0.0</mean>
              <stddev>1.7e-2</stddev>
            </noise>
          </y>
          <z>
            <noise type="gaussian">
              <mean>0.0</mean>
              <stddev>1.7e-2</stddev>
            </noise>
          </z>
        </linear_acceleration>
      </imu>
      <plugin name="basic_mobile_bot_imu" filename="libgazebo_ros_imu_sensor.so">
        <initial_orientation_as_reference>false</initial_orientation_as_reference>
        <ros>
          <remapping>~/out:=imu</remapping>
        </ros>
      </plugin>
    </sensor>
  </link>

  <!-- *********************** GPS SETUP *********************************  -->
  <link name="gps_link">
    <sensor name="bmb_gps" type="gps">
      <always_on>true</always_on>
      <update_rate>10.0</update_rate>
      <gps>
        <position_sensing>
          <horizontal>
            <noise type="gaussian">
              <mean>0.0</mean>
              <stddev>1e-2</stddev>
            </noise>
          </horizontal>
          <vertical>
            <noise type="gaussian">
              <mean>0.0</mean>
              <stddev>1</stddev>
            </noise>
          </vertical>
        </position_sensing>
      </gps>
      <!--Plugin de GPS-->
      <plugin name="basic_mobile_bot_gps" filename="libgazebo_ros_gps_sensor.so">
        <ros>
          <!--Mensaje de tipo NavSatFix-->
          <remapping>~/out:=gps/fix</remapping>
        </ros>
      </plugin>
    </sensor>
  </link>

  <!-- *********************** LIDAR SETUP *********************************  -->
      <link name="base_scan">
        <inertial>
          <pose>0 0 0.111 0 0 0</pose>
          <inertia>
            <ixx>0.001</ixx>
            <ixy>0.000</ixy>
            <ixz>0.000</ixz>
            <iyy>0.001</iyy>
            <iyz>0.000</iyz>
            <izz>0.001</izz>
          </inertia>
          <mass>0.125</mass>
        </inertial>

        <collision name="lidar_sensor_collision">
          <pose>0 0 0.111 0 0 0</pose>
          <geometry>
            <cylinder>
              <radius>0.0508</radius>
              <length>0.055</length>
            </cylinder>
          </geometry>
        </collision>

        <visual name="lidar_sensor_visual">
          <pose>0 0 0.121 0 0 0</pose>
          <geometry>
            <mesh>
              <uri>model://turtlebot3_common/meshes/lds.dae</uri>
              <scale>0.001 0.001 0.001</scale>
            </mesh>
          </geometry>
        </visual>

        <sensor name="hls_lfcd_lds" type="ray">
          <always_on>true</always_on>
          <visualize>true</visualize>
          <pose>0 0 0.121 0 0 0</pose>
          <update_rate>5</update_rate>
          <ray>
            <scan>
              <horizontal>
                <samples>360</samples>
                <resolution>1.000000</resolution>
                <min_angle>0.000000</min_angle>
                <max_angle>6.280000</max_angle>
              </horizontal>
            </scan>
            <range>
              <min>0.120000</min>
              <max>3.5</max>
              <resolution>0.015000</resolution>
            </range>
            <noise>
              <type>gaussian</type>
              <mean>0.0</mean>
              <stddev>0.01</stddev>
            </noise>
          </ray>
          <plugin name="turtlebot3_laserscan" filename="libgazebo_ros_ray_sensor.so">
            <ros>
                <!-- <namespace>/tb3</namespace> -->
                <remapping>~/out:=scan</remapping>
            </ros>
            <output_type>sensor_msgs/LaserScan</output_type>
            <frame_name>base_scan</frame_name>
          </plugin>
        </sensor>
      </link>

  <!-- *********************** CAMERAS SETUP *********************************  -->
      <link name="camera_link">
        <inertial>
          <pose>0.069 -0.047 0.107 0 0 0</pose>
          <inertia>
            <ixx>0.001</ixx>
            <ixy>0.000</ixy>
            <ixz>0.000</ixz>
            <iyy>0.001</iyy>
            <iyz>0.000</iyz>
            <izz>0.001</izz>
          </inertia>
          <mass>0.035</mass>
        </inertial>
        <collision name="collision">
          <pose>0 0.047 -0.005 0 0 0</pose>
          <geometry>
            <box>
              <size>0.008 0.130 0.022</size>
            </box>
          </geometry>
        </collision>

        <pose>0.069 -0.047 0.107 0 0 0</pose>

        <sensor name="intel_realsense_r200_depth" type="depth">
          <always_on>1</always_on>
          <update_rate>5</update_rate>
          <pose>0.064 -0.047 0.107 0 0 0</pose>
          <camera name="realsense_depth_camera">
          </camera>
          <plugin name="intel_realsense_r200_depth_driver" filename="libgazebo_ros_camera.so">
            <ros>
            </ros>
            <camera_name>intel_realsense_r200_depth</camera_name>
            <frame_name>camera_depth_frame</frame_name>
            <hack_baseline>0.07</hack_baseline>
            <min_depth>0.001</min_depth>
            <max_depth>5.0</max_depth>
          </plugin>
        </sensor>

        <collision name="collision">
          <pose>0 0.047 -0.005 0 0 0</pose>
          <geometry>
            <box>
              <size>0.008 0.130 0.022</size>
            </box>
          </geometry>
        </collision>
        <pose>0.069 -0.047 0.107 0 0 0</pose>
      </link>

  <!-- *********************** DRIVE WHEELS ******************************  -->
  <!-- Rear Left Wheel       -->
  <link name="drivewhl_rl_link">

    <inertial>
      <mass>0.3</mass>
      <inertia>
        <ixx>0.000354</ixx>
        <ixy>0</ixy>
        <ixz>0</ixz>
        <iyy>0.000354</iyy>
        <iyz>0</iyz>
        <izz>0.00054</izz>
      </inertia>
    </inertial>

    <!--      X    Y    Z     ROLL  PITCH   YAW     -->
    <pose>-0.084 0.1175 0.058 0 1.570796 1.570796</pose>
    <!-- Y = 0.0875m + wheel_length/2 -->
    <collision name="drivewhl_rl_collision">
      <geometry>
        <cylinder>
          <radius>0.058</radius>
          <length>0.06</length>
        </cylinder>
      </geometry>
        <surface>
          <friction>
            <ode>
              <mu>1</mu>
              <mu2>1</mu2>
              <slip1>0</slip1>
              <slip2>0</slip2>
            </ode>
          </friction>
          <contact>
            <ode>
              <soft_cfm>0</soft_cfm>
              <soft_erp>0.2</soft_erp>
              <kp>1e+13</kp>
              <kd>1</kd>
              <max_vel>0.01</max_vel>
              <min_depth>0.01</min_depth>
            </ode>
          </contact>
        </surface>
    </collision>

    <visual name="drivewhl_rl_visual">
      <geometry>
        <cylinder>
          <radius>0.058</radius>
          <length>0.06</length>
        </cylinder>
      </geometry>
    </visual>
  </link>

  <!-- Rear Right Wheel      -->
  <link name="drivewhl_rr_link">

    <inertial>
      <mass>0.3</mass>
      <inertia>
        <ixx>0.000354</ixx>
        <ixy>0</ixy>
        <ixz>0</ixz>
        <iyy>0.000354</iyy>
        <iyz>0</iyz>
        <izz>0.00054</izz>
      </inertia>
    </inertial>

    <pose>-0.084 -0.1175 0.058 0 1.570796 1.570796</pose>
    
    <collision name="drivewhl_rr_collision">
      <geometry>
        <cylinder>
          <radius>0.058</radius>
          <length>0.06</length>
        </cylinder>
      </geometry>
        <surface>
          <friction>
            <ode>
              <mu>1</mu>
              <mu2>1</mu2>
              <slip1>0</slip1>
              <slip2>0</slip2>
            </ode>
          </friction>
          <contact>
            <ode>
              <soft_cfm>0</soft_cfm>
              <soft_erp>0.2</soft_erp>
              <kp>1e+13</kp>
              <kd>1</kd>
              <max_vel>0.01</max_vel>
              <min_depth>0.01</min_depth>
            </ode>
          </contact>
        </surface>
    </collision>

    <visual name="drivewhl_rr_visual">
      <geometry>
        <cylinder>
          <radius>0.058</radius>
          <length>0.06</length>
        </cylinder>
      </geometry>
    </visual>
  </link>

   <!-- Front Left Wheel     -->
  <link name="drivewhl_fl_link">

    <inertial>
      <mass>0.3</mass>
      <inertia>
        <ixx>0.000354</ixx>
        <ixy>0</ixy>
        <ixz>0</ixz>
        <iyy>0.000354</iyy>
        <iyz>0</iyz>
        <izz>0.00054</izz>
      </inertia>
    </inertial>

    <!--      X    Y    Z alpha beta     gamma     -->
    <pose>0.084 0.1175 0.058 0 1.570796 1.570796</pose>
    
    <collision name="drivewhl_fl_collision">
      <geometry>
        <cylinder>
          <radius>0.058</radius>
          <length>0.06</length>
        </cylinder>
      </geometry>
        <surface>
          <friction>
            <ode>
              <mu>1</mu>
              <mu2>1</mu2>
              <slip1>0</slip1>
              <slip2>0</slip2>
            </ode>
          </friction>
          <contact>
            <ode>
              <soft_cfm>0</soft_cfm>
              <soft_erp>0.2</soft_erp>
              <kp>1e+13</kp>
              <kd>1</kd>
              <max_vel>0.01</max_vel>
              <min_depth>0.01</min_depth>
            </ode>
          </contact>
        </surface>
    </collision>

    <visual name="drivewhl_fl_visual">
      <geometry>
        <cylinder>
          <radius>0.058</radius>
          <length>0.06</length>
        </cylinder>
      </geometry>
    </visual>
  </link>

  <!-- Front Right Wheel      -->
  <link name="drivewhl_fr_link">

    <inertial>
      <mass>0.3</mass>
      <inertia>
        <ixx>0.000354</ixx>
        <ixy>0</ixy>
        <ixz>0</ixz>
        <iyy>0.000354</iyy>
        <iyz>0</iyz>
        <izz>0.00054</izz>
      </inertia>
    </inertial>

    <pose>0.084 -0.1175 0.058 0 1.570796 1.570796</pose>
    
    <collision name="drivewhl_fr_collision">
      <geometry>
        <cylinder>
          <radius>0.058</radius>
          <length>0.06</length>
        </cylinder>
      </geometry>
        <surface>
          <friction>
            <ode>
              <mu>1</mu>
              <mu2>1</mu2>
              <slip1>0</slip1>
              <slip2>0</slip2>
            </ode>
          </friction>
          <contact>
            <ode>
              <soft_cfm>0</soft_cfm>
              <soft_erp>0.2</soft_erp>
              <kp>1e+13</kp>
              <kd>1</kd>
              <max_vel>0.01</max_vel>
              <min_depth>0.01</min_depth>
            </ode>
          </contact>
        </surface>
    </collision>

    <visual name="drivewhl_fr_visual">
      <geometry>
        <cylinder>
          <radius>0.058</radius>
          <length>0.06</length>
        </cylinder>
      </geometry>
    </visual>
  </link>

  <!-- ************************ JOINTS ***********************************  -->
  <!-- Pose of the joint is the same as the child link frame -->
  <!-- Axis is the axis of rotation relative to the child link frame -->
  
  <joint name="base_joint" type="fixed">
    <parent>base_footprint</parent>
    <child>base_link</child>
    <pose>0 0 0 0 0 0</pose>
  </joint>

  <joint name="drivewhl_rl_joint" type="revolute">
    <parent>base_link</parent>
    <child>drivewhl_rl_link</child>
    <pose>0 0 0 0 0 0</pose>
    <axis>
      <xyz>0 0 1</xyz>
    </axis>
  </joint>

  <joint name="drivewhl_rr_joint" type="revolute">
    <parent>base_link</parent>
    <child>drivewhl_rr_link</child>
    <pose>0 0 0 0 0 0</pose>
    <axis>
      <xyz>0 0 1</xyz>
    </axis>
  </joint>

    <joint name="drivewhl_fl_joint" type="revolute">
    <parent>base_link</parent>
    <child>drivewhl_fl_link</child>
    <pose>0 0 0 0 0 0</pose>
    <axis>
      <xyz>0 0 1</xyz>
    </axis>
  </joint>

    <joint name="drivewhl_fr_joint" type="revolute">
    <parent>base_link</parent>
    <child>drivewhl_fr_link</child>
    <pose>0 0 0 0 0 0</pose>
    <axis>
      <xyz>0 0 1</xyz>
    </axis>
  </joint>

  <joint name="imu_joint" type="fixed">
    <parent>base_link</parent>
    <child>imu_link</child>
    <pose>0 0 0 0 0 0</pose>
  </joint>  

  <joint name="gps_joint" type="fixed">
    <parent>base_link</parent>
    <child>gps_link</child>
    <pose>0 0 0 0 0 0</pose>
  </joint>  
  
  <joint name="lidar_joint" type="fixed">
     <parent>base_link</parent>
     <child>base_scan</child>
     <pose>0 0 0.121 0 0 0</pose>
        <axis>
          <xyz>0 0 1</xyz>
        </axis>
  </joint>

  <joint name="camera_joint" type="fixed">
     <parent>base_link</parent>
     <child>camera_link</child>
     <pose>0.0 -0.065 0.094 0 0 0</pose>
     <axis>
       <xyz>0 0 1</xyz>
     </axis>
  </joint>

  <joint name="camera_rgb_joint" type="fixed">
     <parent>camera_link</parent>
     <child>camera_rgb_frame</child>
     <pose>0.0 0.018 0.013 0 0 0</pose>
     <axis>
       <xyz>0 0 1</xyz>
     </axis>
  </joint>


 <!-- *********************** WHEEL ODOMETRY ***************************    -->
  <plugin name='skid_steer_drive' filename='libgazebo_ros_diff_drive.so'>

    <!-- Number of wheel pairs -->
    <num_wheel_pairs>2</num_wheel_pairs>
    
    <!-- wheels0 FRONT wheels-->
    <left_joint>drivewhl_fl_joint</left_joint>
    <right_joint>drivewhl_fr_joint</right_joint>

    <!-- wheels1 REAR wheels-->
    <left_joint>drivewhl_rl_joint</left_joint>
    <right_joint>drivewhl_rr_joint</right_joint>

    <!-- kinematics -->
    <wheel_separation>0.26</wheel_separation>
    <wheel_separation>0.26</wheel_separation>

    <wheel_diameter>0.116</wheel_diameter>
    <wheel_diameter>0.116</wheel_diameter>

    <!-- Receive velocity commands on this ROS topic -->
    <command_topic>cmd_vel</command_topic>

    <!-- limits -->
    <max_wheel_torque>20</max_wheel_torque>
    <max_wheel_acceleration>1.0</max_wheel_acceleration>

    <!-- output CAMBIO -->
    <publish_odom>true</publish_odom>
    <publish_odom_tf>true</publish_odom_tf>
    <publish_wheel_tf>false</publish_wheel_tf>

    <odometry_topic>odom</odometry_topic>
    <odometry_frame>odom</odometry_frame>
    <robot_base_frame>base_footprint</robot_base_frame>

    <ros>
       <!-- <namespace>/tb3</namespace> CAMBIO -->
       <!--since gazebo_plugins publish tf topic in global namespace /tf only and it
         cannot be remapped like (namespace/tf) through launch arguments -->
       <remapping>/tf:=tf</remapping>
    </ros>

    <update_rate>30</update_rate>

  </plugin>

 <!-- *********************** JOINT STATE PUBLISHER *********************   -->
  
  <plugin name="basic_mobile_bot_joint_state" filename="libgazebo_ros_joint_state_publisher.so">
    <ros>
      <remapping>~/out:=joint_states</remapping>
    </ros>
    <update_rate>30</update_rate>
    <joint_name>drivewhl_rl_joint</joint_name>
    <joint_name>drivewhl_rr_joint</joint_name>
    <joint_name>drivewhl_fl_joint</joint_name>
    <joint_name>drivewhl_fr_joint</joint_name>
  </plugin>   
  
  </model>
</sdf>

